Workbook

Sheet 🏠 Bienvenida
B5: Herramienta de Estudio de Mercado y Factibilidad
B7: Cadencia de Reservas™ | Academia MundoBNB | 2026
B10: Este libro te ayuda a decidir si tu propiedad funciona mejor como renta vacacional (Airbnb) o como renta tradicional. Úsalo así: completa la información paso por paso (1 → 2 → 3 → 4 → 5). El libro hace los cálculos por ti. Al final, la pestaña "5. Resumen" te dice si el negocio es viable y cómo se compara con rentarla de forma tradicional.
B12: CÓMO USAR ESTE LIBRO
B14: PASO 1 → Llena el perfil de tu propiedad
B15: Ve a la pestaña "1. Perfil" y completa todas las celdas en azul: nombre, ciudad, tipo de propiedad, recámaras, baños, amenidades, tu hipoteca o renta del inmueble, y cuánto te darían por rentarla de forma tradicional. ⚠️ No olvides escribir la FECHA DEL ESTUDIO (celda C30) — esa fecha se usa para calcular qué tan rápido acumulan reviews tus competidores.
B17: PASO 2 → Investiga el mercado (tus competidoras)
B18: Ve a la pestaña "2. Mercado". Busca en Airbnb las 10 propiedades más parecidas a la tuya (mismo tamaño, zona, estilo). Para cada una, escribe el precio por noche que aparece en Airbnb para cada mes del año — ese precio es BRUTO (ya incluye la comisión de Airbnb). En la FILA AMARILLA (fila 14) escribe los datos de TU propiedad para compararla directo. El libro saca los promedios, ingresos y velocidad de reviews automáticamente.
B20: PASO 3 → Identifica el "techo" del mercado
B21: Ve a la pestaña "3. Top Propiedades" y registra las 5 propiedades que más dinero generan en tu zona. Estas te muestran hasta dónde puede llegar tu propiedad si haces las mejoras correctas — es tu meta a alcanzar.
B23: PASO 4a → Factibilidad real (con TUS números actuales)
B24: Ve a la pestaña "4a. Factibilidad" e ingresa tus costos reales: limpieza, mantenimiento, servicios, hipoteca, etc. Los ingresos llegan automáticamente desde el Estudio de Mercado (basado en TU propiedad, fila 14). 🔔 No olvides elegir el % de RESERVA mensual en la celda amarilla B48 (recomendado 10–15%). El libro te dice si hay utilidad y si supera la renta convencional.
... B35: CÓDIGO DE COLORES DEL LIBRO
B36: Texto AZUL | C36: Tú lo escribes — son las celdas donde TÚ debes llenar la información
B37: Texto NEGRO | C37: Fórmulas automáticas — NO las toques, se calculan solas
B38: Texto VERDE | C38: Conexión entre pestañas — jala datos de otra hoja automáticamente
B39: Fondo AMARILLO | C39: Atención — dato importante que debes revisar o seleccionar
B40: Fondo VERDE | C40: ¡Buena noticia! — indicador positivo o viable
B41: Fondo ROJO | C41: Alerta — indicador negativo, necesita ajuste
B43: Juan Pablo Téllez Girón | Academia MundoBNB | Cadencia de Reservas™ | mundobnb.com

Sheet 1. Perfil
B1: Cadencia de Reservas™ — Perfil de la Propiedad
B2: 💱 Moneda del estudio | C2: USD - Dólar EE.UU. | D2: ⚠ IMPORTANTE: Escribe la moneda en la que llenarás los montos (ej. MXN, USD, EUR, COP, ARS, CLP, BRL, etc.)
B3: 1. Identificación de la propiedad
B4: Nombre de la propiedad | C4: Ej. Estudio Long Island
B5: Tipo de alojamiento | C5: Ej. Departamento completo
B6: Ciudad / Zona | C6: Ej. Elmont, NY | D6: Ciudad y colonia o zona específica.
B7: Link Airbnb / Booking | C7: Ej. https://www.airbnb.com/rooms/123456 | D7: https://www.airbnb.mx/rooms/51667347
B8: Anfitrión / Operador | C8: Ej. Nombre del anfitrión o empresa | D8: Quién opera y aparece como host visible.
B9: 2. Capacidad y configuración
B10: Recámaras
B11: Camas | D11: Total de camas (incluye sofá-camas).
B12: Baños
B13: Capacidad máxima (huéspedes)
B14: Metros cuadrados
B15: Estacionamiento (cajones)
B16: 3. Posicionamiento y amenidades
B17: Categoría / segmento | C17: Ej. Estándar | D17: Nivel objetivo del listado.
B18: Amenidades destacadas | C18: Ej. WiFi, cocina equipada, A/C | D18: Lista corta de lo más vendible del listado.
B19: Diferenciador principal | C19: Ej. A 5 min de la estación, ideal para commuters | D19: 1 frase. Ej. Única con vista al mar en la zona.
B20: 4. Operación y costos
B21: Tarifa base por noche | D21: Tarifa de lista (sin descuentos). Resaltada porque es clave.
B22: Renta / hipoteca mensual | D22: Costo fijo mensual de tener la propiedad.
B23: Tarifa de Limpieza | D23: Tu costo de una limpieza
B24: Esquema de comisión Airbnb | C24: Split Fee (15% huésped · 3% anfitrión) | D24: Elige: Split Fee (3%) o Host Only Fee (15.5%).
B25: Comisión efectiva (cálculo) | C25: =IF(C24="Host Only Fee (15.5% anfitrión)",0.155,0.03) -> 0.03 | D25: Se calcula automáticamente.
B26: 5. Datos del estudio
B27: Autor del estudio | C27: Ej. Tu nombre
B28: Mercado / submercado analizado | C28: Ej. Tulum Centro – casas 2 recámaras | D28: Define el segmento que vas a comparar en la pestaña 2. Mercado.
B29: Notas adicionales | C29: Ej. Contexto relevante del estudio
B30: Fecha de captura del estudio | C30: 46184 | D30: ⚠ Obligatorio. Se usa en '2. Mercado' para velocidad de reviews/año.
B31: Cadencia de Reservas™ | Academia MundoBNB | 2026

Sheet 2. Mercado
B1: Cadencia de Reservas™ — Estudio de Mercado | 10 Propiedades Competidoras
B2: # | C2: Enlace al anuncio (Airbnb/Booking) | D2: Rec. | E2: Camas | F2: Baños | G2: Pax | H2: Reviews | I2: Rating | J2: Fecha 1er review | K2: 🔒 Años activa (desde 1er review) | L2: 🔒 Prom. reviews/año (velocidad) | M2: Ene | N2: Feb | O2: Mar | P2: Abr | Q2: May | R2: Jun | S2: Jul | T2: Ago | U2: Sep | V2: Oct | W2: Nov | X2: Dic | Y2: 🔒 Prom. anual | Z2: Ocup. % (AirDNA / All the Rooms) | AA2: 🔒 Ing. mensual est. (sin comisión Airbnb) | AB2: 🔒 Ing. anual est. (sin comisión Airbnb) | AC2: ADR (AirDNA / All the Rooms) | AD2: 🔒 Ing. mensual según AirDNA | AE2: Amenidades Importantes | AF2: Notas análisis (funnel: foto→título→desc→calendario→reviews→anfitrión) | AG2: Tipo anfitrión
B3: Ejemplo | C3: https://www.airbnb.com/rooms/EJEMPLO | D3: 2 | E3: 3 | F3: 1.5 | G3: 4 | H3: 50 | I3: 4.8 | J3: 44197 | K3: =IF(OR('1. Perfil'!$C$30="",J3=""),"",IFERROR(('1. Perfil'!$C$30-J3)/365,"")) -> 5.4438356 | L3: =IF(OR('1. Perfil'!$C$30="",J3=""),"",IFERROR(H3/MAX(1,('1. Perfil'!$C$30-J3)/365),"")) -> 9.1847006 | M3: 180 | N3: 185 | O3: 200 | P3: 195 | Q3: 210 | R3: 175 | S3: 170 | T3: 170 | U3: 165 | V3: 175 | W3: 185 | X3: 195 | Y3: =IFERROR(AVERAGEIF(M3:X3,"<>0",M3:X3),"") -> 183.75 | Z3: 0.55 | AA3: =IFERROR(Y3*Z3*30*(1-'1. Perfil'!$C$25),"") -> 2940.9188 | AB3: =IFERROR(AA3*12,"") -> 35291.025 | AC3: 185 | AD3: =IFERROR(Z3*AC3*30,"") -> 3052.5 | AE3: Alberca, WiFi, A/C, Cocina equipada, Estacionamiento | AF3: Buenas fotos, título claro y descripción detallada. Anfitrión responde rápido. Calendario abierto 6+ meses. | AG3: Individual
B4: 1 | K4: =IF(OR('1. Perfil'!$C$30="",J4=""),"",IFERROR(('1. Perfil'!$C$30-J4)/365,"")) | L4: =IF(OR('1. Perfil'!$C$30="",J4=""),"",IFERROR(H4/MAX(1,('1. Perfil'!$C$30-J4)/365),"")) | Y4: =IFERROR(AVERAGEIF(M4:X4,"<>0",M4:X4),"") | AA4: =IFERROR(Y4*Z4*30*(1-'1. Perfil'!$C$25),"") | AB4: =IFERROR(AA4*12,"") | AD4: =IFERROR(Z4*AC4*30,"") -> 0
B5: 2 | K5: =IF(OR('1. Perfil'!$C$30="",J5=""),"",IFERROR(('1. Perfil'!$C$30-J5)/365,"")) | L5: =IF(OR('1. Perfil'!$C$30="",J5=""),"",IFERROR(H5/MAX(1,('1. Perfil'!$C$30-J5)/365),"")) | Y5: =IFERROR(AVERAGEIF(M5:X5,"<>0",M5:X5),"") | AA5: =IFERROR(Y5*Z5*30*(1-'1. Perfil'!$C$25),"") | AB5: =IFERROR(AA5*12,"") | AD5: =IFERROR(Z5*AC5*30,"") -> 0
B6: 3 | K6: =IF(OR('1. Perfil'!$C$30="",J6=""),"",IFERROR(('1. Perfil'!$C$30-J6)/365,"")) | L6: =IF(OR('1. Perfil'!$C$30="",J6=""),"",IFERROR(H6/MAX(1,('1. Perfil'!$C$30-J6)/365),"")) | Y6: =IFERROR(AVERAGEIF(M6:X6,"<>0",M6:X6),"") | AA6: =IFERROR(Y6*Z6*30*(1-'1. Perfil'!$C$25),"") | AB6: =IFERROR(AA6*12,"") | AD6: =IFERROR(Z6*AC6*30,"") -> 0
B7: 4 | K7: =IF(OR('1. Perfil'!$C$30="",J7=""),"",IFERROR(('1. Perfil'!$C$30-J7)/365,"")) | L7: =IF(OR('1. Perfil'!$C$30="",J7=""),"",IFERROR(H7/MAX(1,('1. Perfil'!$C$30-J7)/365),"")) | Y7: =IFERROR(AVERAGEIF(M7:X7,"<>0",M7:X7),"") | AA7: =IFERROR(Y7*Z7*30*(1-'1. Perfil'!$C$25),"") | AB7: =IFERROR(AA7*12,"") | AD7: =IFERROR(Z7*AC7*30,"") -> 0
B8: 5 | K8: =IF(OR('1. Perfil'!$C$30="",J8=""),"",IFERROR(('1. Perfil'!$C$30-J8)/365,"")) | L8: =IF(OR('1. Perfil'!$C$30="",J8=""),"",IFERROR(H8/MAX(1,('1. Perfil'!$C$30-J8)/365),"")) | Y8: =IFERROR(AVERAGEIF(M8:X8,"<>0",M8:X8),"") | AA8: =IFERROR(Y8*Z8*30*(1-'1. Perfil'!$C$25),"") | AB8: =IFERROR(AA8*12,"") | AD8: =IFERROR(Z8*AC8*30,"") -> 0
B9: 6 | K9: =IF(OR('1. Perfil'!$C$30="",J9=""),"",IFERROR(('1. Perfil'!$C$30-J9)/365,"")) | L9: =IF(OR('1. Perfil'!$C$30="",J9=""),"",IFERROR(H9/MAX(1,('1. Perfil'!$C$30-J9)/365),"")) | Y9: =IFERROR(AVERAGEIF(M9:X9,"<>0",M9:X9),"") | AA9: =IFERROR(Y9*Z9*30*(1-'1. Perfil'!$C$25),"") | AB9: =IFERROR(AA9*12,"") | AD9: =IFERROR(Z9*AC9*30,"") -> 0
B10: 7 | K10: =IF(OR('1. Perfil'!$C$30="",J10=""),"",IFERROR(('1. Perfil'!$C$30-J10)/365,"")) | L10: =IF(OR('1. Perfil'!$C$30="",J10=""),"",IFERROR(H10/MAX(1,('1. Perfil'!$C$30-J10)/365),"")) | Y10: =IFERROR(AVERAGEIF(M10:X10,"<>0",M10:X10),"") | AA10: =IFERROR(Y10*Z10*30*(1-'1. Perfil'!$C$25),"") | AB10: =IFERROR(AA10*12,"") | AD10: =IFERROR(Z10*AC10*30,"") -> 0
B11: 8 | K11: =IF(OR('1. Perfil'!$C$30="",J11=""),"",IFERROR(('1. Perfil'!$C$30-J11)/365,"")) | L11: =IF(OR('1. Perfil'!$C$30="",J11=""),"",IFERROR(H11/MAX(1,('1. Perfil'!$C$30-J11)/365),"")) | Y11: =IFERROR(AVERAGEIF(M11:X11,"<>0",M11:X11),"") | AA11: =IFERROR(Y11*Z11*30*(1-'1. Perfil'!$C$25),"") | AB11: =IFERROR(AA11*12,"") | AD11: =IFERROR(Z11*AC11*30,"") -> 0
B12: 9 | K12: =IF(OR('1. Perfil'!$C$30="",J12=""),"",IFERROR(('1. Perfil'!$C$30-J12)/365,"")) | L12: =IF(OR('1. Perfil'!$C$30="",J12=""),"",IFERROR(H12/MAX(1,('1. Perfil'!$C$30-J12)/365),"")) | Y12: =IFERROR(AVERAGEIF(M12:X12,"<>0",M12:X12),"") | AA12: =IFERROR(Y12*Z12*30*(1-'1. Perfil'!$C$25),"") | AB12: =IFERROR(AA12*12,"") | AD12: =IFERROR(Z12*AC12*30,"") -> 0
B13: 10 | K13: =IF(OR('1. Perfil'!$C$30="",J13=""),"",IFERROR(('1. Perfil'!$C$30-J13)/365,"")) | L13: =IF(OR('1. Perfil'!$C$30="",J13=""),"",IFERROR(H13/MAX(1,('1. Perfil'!$C$30-J13)/365),"")) | Y13: =IFERROR(AVERAGEIF(M13:X13,"<>0",M13:X13),"") | AA13: =IFERROR(Y13*Z13*30*(1-'1. Perfil'!$C$25),"") | AB13: =IFERROR(AA13*12,"") | AD13: =IFERROR(Z13*AC13*30,"") -> 0
B14: MI PROPIEDAD | D14: ='1. Perfil'!C10 -> 0 | E14: ='1. Perfil'!C11 -> 0 | F14: ='1. Perfil'!C12 -> 0 | G14: ='1. Perfil'!C13 -> 0 | K14: =IF(OR('1. Perfil'!$C$30="",J14=""),"",IFERROR(('1. Perfil'!$C$30-J14)/365,"")) | L14: =IF(OR('1. Perfil'!$C$30="",J14=""),"",IFERROR(H14/MAX(1,('1. Perfil'!$C$30-J14)/365),"")) | Y14: =IFERROR(AVERAGEIF(M14:X14,"<>0",M14:X14),"") | AA14: =IFERROR(Y14*Z14*30*(1-'1. Perfil'!$C$25),"") | AB14: =IFERROR(AA14*12,"") | AD14: =IFERROR(Z14*AC14*30,"") -> 0
B15: PROMEDIOS DEL MERCADO | H15: =IFERROR(AVERAGEIF(H4:H14,"<>0",H4:H14),"") | I15: =IFERROR(AVERAGEIF(I4:I14,"<>0",I4:I14),"") | L15: =IFERROR(AVERAGEIF(L4:L14,"<>0",L4:L14),"") | M15: =IFERROR(AVERAGEIF(M4:M13,"<>0",M4:M13),"") | N15: =IFERROR(AVERAGEIF(N4:N13,"<>0",N4:N13),"") | O15: =IFERROR(AVERAGEIF(O4:O13,"<>0",O4:O13),"") | P15: =IFERROR(AVERAGEIF(P4:P13,"<>0",P4:P13),"") | Q15: =IFERROR(AVERAGEIF(Q4:Q13,"<>0",Q4:Q13),"") | R15: =IFERROR(AVERAGEIF(R4:R13,"<>0",R4:R13),"") | S15: =IFERROR(AVERAGEIF(S4:S13,"<>0",S4:S13),"") | T15: =IFERROR(AVERAGEIF(T4:T13,"<>0",T4:T13),"") | ... X15: =IFERROR(AVERAGEIF(X4:X13,"<>0",X4:X13),"") | Y15: =IFERROR(AVERAGE(Y4:Y13),"") | Z15: =IFERROR(AVERAGE(Z4:Z13),"") | AA15: =IFERROR(AVERAGE(AA4:AA13),"") | AB15: =IFERROR(AVERAGE(AB4:AB14),"") | AC15: =IFERROR(AVERAGEIF(AC4:AC14,"<>0",AC4:AC14),"") | AD15: =IFERROR(AVERAGEIF(AD4:AD14,"<>0",AD4:AD14),"")
B16: Cadencia de Reservas™ | Academia MundoBNB | 2026 | Actualiza mensualmente
B17: 📌 Leyenda: 🔒 = Se calcula solo (no editar) 🟨 Amarillo claro = Tu propiedad
B18: =IF('1. Perfil'!C30="","⚠ Falta fecha del estudio en '1. Perfil'!C30","📅 Fecha del estudio: "&TEXT('1. Perfil'!C30,"dd/mmm/aaaa")) -> 📅 Fecha del estudio: 11/jun/2026

Sheet 3. Top Propiedades
B1: Cadencia de Reservas™ — Top Propiedades | Techo de Mercado
B2: Las 5 propiedades de mayor revenue en tu zona según AirDNA. Definen hasta dónde puede llegar tu propiedad.
B3: # | C3: Enlace | D3: Rec. | E3: Baños | F3: Huéspedes | G3: Reviews | H3: Rating | I3: Fecha 1er review | J3: 🔒 Años activa (desde 1er review) | K3: 🔒 Prom. reviews/año (velocidad) | L3: ADR (AirDNA) | M3: Ocup. % (AirDNA) | N3: 🔒 Revenue est./mes | O3: 🔒 Revenue est./año | P3: ¿Qué las hace top? | Q3: ¿Qué puedo copiar?
B4: Ejemplo | C4: https://www.airbnb.com/rooms/EJEMPLO | D4: 3 | E4: 2 | F4: 6 | G4: 120 | H4: 4.9 | I4: 43800 | J4: =IF(OR('1. Perfil'!$C$30="",I4=""),"",IFERROR(('1. Perfil'!$C$30-I4)/365,"")) -> 6.5315068 | K4: =IF(OR('1. Perfil'!$C$30="",I4=""),"",IFERROR(G4/MAX(1,('1. Perfil'!$C$30-I4)/365),"")) -> 18.372483 | L4: 250 | M4: 0.65 | N4: =IFERROR(L4*M4*30,"") -> 4875 | O4: =IFERROR(N4*12,"") -> 58500 | P4: Diseño moderno, decoración temática, fotos profesionales | Q4: Renovar fotos, agregar amenidades premium (jacuzzi, vista)
B5: 1 | J5: =IF(OR('1. Perfil'!$C$30="",I5=""),"",IFERROR(('1. Perfil'!$C$30-I5)/365,"")) | K5: =IF(OR('1. Perfil'!$C$30="",I5=""),"",IFERROR(G5/MAX(1,('1. Perfil'!$C$30-I5)/365),"")) | N5: =IFERROR(L5*M5*30,"") -> 0 | O5: =IFERROR(N5*12,"") -> 0
B6: 2 | J6: =IF(OR('1. Perfil'!$C$30="",I6=""),"",IFERROR(('1. Perfil'!$C$30-I6)/365,"")) | K6: =IF(OR('1. Perfil'!$C$30="",I6=""),"",IFERROR(G6/MAX(1,('1. Perfil'!$C$30-I6)/365),"")) | N6: =IFERROR(L6*M6*30,"") -> 0 | O6: =IFERROR(N6*12,"") -> 0
B7: 3 | J7: =IF(OR('1. Perfil'!$C$30="",I7=""),"",IFERROR(('1. Perfil'!$C$30-I7)/365,"")) | K7: =IF(OR('1. Perfil'!$C$30="",I7=""),"",IFERROR(G7/MAX(1,('1. Perfil'!$C$30-I7)/365),"")) | N7: =IFERROR(L7*M7*30,"") -> 0 | O7: =IFERROR(N7*12,"") -> 0
B8: 4 | J8: =IF(OR('1. Perfil'!$C$30="",I8=""),"",IFERROR(('1. Perfil'!$C$30-I8)/365,"")) | K8: =IF(OR('1. Perfil'!$C$30="",I8=""),"",IFERROR(G8/MAX(1,('1. Perfil'!$C$30-I8)/365),"")) | N8: =IFERROR(L8*M8*30,"") -> 0 | O8: =IFERROR(N8*12,"") -> 0
B9: 5 | J9: =IF(OR('1. Perfil'!$C$30="",I9=""),"",IFERROR(('1. Perfil'!$C$30-I9)/365,"")) | K9: =IF(OR('1. Perfil'!$C$30="",I9=""),"",IFERROR(G9/MAX(1,('1. Perfil'!$C$30-I9)/365),"")) | N9: =IFERROR(L9*M9*30,"") -> 0 | O9: =IFERROR(N9*12,"") -> 0
B11: TECHO DE MERCADO
B12: 🔒 Revenue máximo (top 1) | C12: =IFERROR(MAX(N5:N9),"") -> 0 | D12: ← calculado automático
B13: 🔒 Revenue promedio top 5 | C13: =IFERROR(AVERAGE(N5:N9),"") -> 0 | D13: ← calculado automático
B14: 🔒 Tarifa prom. noche (top 5) | C14: =IFERROR(AVERAGE(L5:L9),"") | D14: ← calculado automático
B15: 🔒 Brecha vs mercado base | C15: =IFERROR(N13-'2. Mercado'!AA15,"") | D15: ← calculado automático
B16: 📌 Leyenda: 🔒 = Se calcula solo (no editar)
B17: =IF('1. Perfil'!C30="","⚠ Falta fecha del estudio en '1. Perfil'!C30","📅 Fecha del estudio: "&TEXT('1. Perfil'!C30,"dd/mmm/aaaa")) -> 📅 Fecha del estudio: 11/jun/2026

Sheet 4a. Factibilidad
B1: Cadencia de Reservas™ — Estudio de Factibilidad | 12 Meses
B2: Ingresos automáticos desde el Estudio de Mercado. Ingresa tus costos. Los costos FIJOS: solo escribe en Enero — los otros meses se repiten solos.
B3: CONCEPTO | C3: Ene | D3: Feb | E3: Mar | F3: Abr | G3: May | H3: Jun | I3: Jul | J3: Ago | K3: Sep | L3: Oct | M3: Nov | N3: Dic | O3: Total anual | P3: Prom. mensual | Q3: Notas / referencia
B4: INGRESOS ESTIMADOS — provienen del Estudio de Mercado (Tab 2)
B5: Tarifa promedio de mercado (por mes) | C5: =IFERROR('2. Mercado'!M14,"") -> 0 | D5: =IFERROR('2. Mercado'!N14,"") -> 0 | E5: =IFERROR('2. Mercado'!O14,"") -> 0 | F5: =IFERROR('2. Mercado'!P14,"") -> 0 | G5: =IFERROR('2. Mercado'!Q14,"") -> 0 | H5: =IFERROR('2. Mercado'!R14,"") -> 0 | I5: =IFERROR('2. Mercado'!S14,"") -> 0 | J5: =IFERROR('2. Mercado'!T14,"") -> 0 | ... N5: =IFERROR('2. Mercado'!X14,"") -> 0 | O5: =IFERROR(AVERAGE(C5:N5),"") -> 0 | P5: ← promedio anual | Q5: ← desde Tab 2 · Mercado — promedio de 10 propiedades
B6: Ocupación estimada % (mensual) | C6: =IFERROR('2. Mercado'!$Z$14,"") -> 0 | D6: =IFERROR('2. Mercado'!$Z$14,"") -> 0 | E6: =IFERROR('2. Mercado'!$Z$14,"") -> 0 | F6: =IFERROR('2. Mercado'!$Z$14,"") -> 0 | G6: =IFERROR('2. Mercado'!$Z$14,"") -> 0 | H6: =IFERROR('2. Mercado'!$Z$14,"") -> 0 | I6: =IFERROR('2. Mercado'!$Z$14,"") -> 0 | J6: =IFERROR('2. Mercado'!$Z$14,"") -> 0 | ... N6: =IFERROR('2. Mercado'!$Z$14,"") -> 0 | O6: =IFERROR(AVERAGE(C6:N6),"") -> 0 | P6: ← promedio anual | Q6: ← Tab 2 · puedes sobreescribir mes a mes con dato de AirDNA
B7: Días del mes | C7: 31 | D7: 28 | E7: 31 | F7: 30 | G7: 31 | H7: 30 | I7: 31 | J7: 31 | K7: 30 | L7: 31 | M7: 30 | N7: 31 | O7: 365 | P7: =O7/12 -> 30.416667 | Q7: Referencia automática
B8: Ingreso por rentas mensual | C8: =IFERROR(C5*C6*C7,0) -> 0 | D8: =IFERROR(D5*D6*D7,0) -> 0 | E8: =IFERROR(E5*E6*E7,0) -> 0 | F8: =IFERROR(F5*F6*F7,0) -> 0 | G8: =IFERROR(G5*G6*G7,0) -> 0 | H8: =IFERROR(H5*H6*H7,0) -> 0 | I8: =IFERROR(I5*I6*I7,0) -> 0 | J8: =IFERROR(J5*J6*J7,0) -> 0 | ... N8: =IFERROR(N5*N6*N7,0) -> 0 | O8: =SUM(C8:N8) -> 0 | P8: =IFERROR(O8/12,"") -> 0 | Q8: tarifa * ocupación * días del mes
B9: Tarifa de limpieza | C9: =IFERROR('1. Perfil'!C23,0) -> 0 | D9: =IFERROR('1. Perfil'!C23,0) -> 0 | E9: =IFERROR('1. Perfil'!C23,0) -> 0 | F9: =IFERROR('1. Perfil'!C23,0) -> 0 | G9: =IFERROR('1. Perfil'!C23,0) -> 0 | H9: =IFERROR('1. Perfil'!C23,0) -> 0 | I9: =IFERROR('1. Perfil'!C23,0) -> 0 | J9: =IFERROR('1. Perfil'!C23,0) -> 0 | K9: =IFERROR('1. Perfil'!C23,0) -> 0 | L9: =IFERROR('1. Perfil'!C23,0) -> 0 | M9: =IFERROR('1. Perfil'!C23,0) -> 0 | N9: =IFERROR('1. Perfil'!C23,0) -> 0 | O9: =IFERROR('1. Perfil'!C23,0) -> 0 | P9: tarifa fija | Q9: ← desde Tab 1 · Perfil
B10: Limpiezas estimadas por mes | O10: =SUM(C10:N10) -> 0 | P10: =IFERROR(O10/12,"") -> 0 | Q10: Ingresa el número de limpiezas por mes
B11: Ingreso por limpiezas (informativo — no se suma) | C11: =IFERROR(C9*C10,0) -> 0 | D11: =IFERROR(D9*D10,0) -> 0 | E11: =IFERROR(E9*E10,0) -> 0 | F11: =IFERROR(F9*F10,0) -> 0 | G11: =IFERROR(G9*G10,0) -> 0 | H11: =IFERROR(H9*H10,0) -> 0 | I11: =IFERROR(I9*I10,0) -> 0 | J11: =IFERROR(J9*J10,0) -> 0 | ... N11: =IFERROR(N9*N10,0) -> 0 | O11: =SUM(C11:N11) -> 0 | P11: =IFERROR(O11/12,"") -> 0 | Q11: Solo visual: la limpieza ya viene incluida en el ingreso por rentas
B12: INGRESO TOTAL MENSUAL | C12: =C8 -> 0 | D12: =D8 -> 0 | E12: =E8 -> 0 | F12: =F8 -> 0 | G12: =G8 -> 0 | H12: =H8 -> 0 | I12: =I8 -> 0 | J12: =J8 -> 0 | ... N12: =N8 -> 0 | O12: =SUM(C12:N12) -> 0 | P12: =IFERROR(O12/12,"") -> 0
B13: COSTOS DE OPERACIÓN — ingresa el gasto real de cada mes
B14: Camarista / servicio de limpieza | O14: =SUM(C14:N14) -> 0 | P14: =IFERROR(O14/12,"") -> 0 | Q14: Por rotación o mensual fijo
B15: Mantenimiento general (persona) | O15: =SUM(C15:N15) -> 0 | P15: =IFERROR(O15/12,"") -> 0
B16: Insumos de limpieza | O16: =SUM(C16:N16) -> 0 | P16: =IFERROR(O16/12,"") -> 0
B17: Insumos de mantenimiento | O17: =SUM(C17:N17) -> 0 | P17: =IFERROR(O17/12,"") -> 0
B18: (agregar concepto) | O18: =SUM(C18:N18) -> 0 | P18: =IFERROR(O18/12,"") -> 0 | Q18: 👉 Espacios libres — agrega aquí cualquier concepto extra a tu discreción
B19: (agregar concepto) | O19: =SUM(C19:N19) -> 0 | P19: =IFERROR(O19/12,"") -> 0
B20: (agregar concepto) | O20: =SUM(C20:N20) -> 0 | P20: =IFERROR(O20/12,"") -> 0
B21: MANTENIMIENTO DE EQUIPOS — celdas amarillas = meses sugeridos
B22: Aire acondicionado | O22: =SUM(C22:N22) -> 0 | P22: =IFERROR(O22/12,"") -> 0 | Q22: Sugerido: Jun y Dic · proratea el costo semestral
B23: Alberca / jacuzzi | O23: =SUM(C23:N23) -> 0 | P23: =IFERROR(O23/12,"") -> 0 | Q23: Mantenimiento semanal o quincenal
B24: Electrodomésticos (refri, lavadora…) | O24: =SUM(C24:N24) -> 0 | P24: =IFERROR(O24/12,"") -> 0 | Q24: Garantías, contratos preventivos
B25: Fumigación | O25: =SUM(C25:N25) -> 0 | P25: =IFERROR(O25/12,"") -> 0 | Q25: Sugerido: Mar, Jun, Sep, Dic (trimestral)
B26: Jardinería / paneles solares | O26: =SUM(C26:N26) -> 0 | P26: =IFERROR(O26/12,"") -> 0
B27: Mantenimiento general extra | O27: =SUM(C27:N27) -> 0 | P27: =IFERROR(O27/12,"") -> 0 | Q27: Reparaciones menores imprevistas
B28: (agregar concepto) | O28: =SUM(C28:N28) -> 0 | P28: =IFERROR(O28/12,"") -> 0 | Q28: 👉 Espacios libres — agrega aquí cualquier concepto extra a tu discreción
B29: (agregar concepto) | O29: =SUM(C29:N29) -> 0 | P29: =IFERROR(O29/12,"") -> 0
B30: (agregar concepto) | O30: =SUM(C30:N30) -> 0 | P30: =IFERROR(O30/12,"") -> 0
B31: COSTOS FIJOS — escribe solo en Enero · los demás meses se repiten solos
B32: Hipoteca o renta del inmueble | C32: =IFERROR('1. Perfil'!C22,0) -> 0 | D32: =$C$32 -> 0 | E32: =$C$32 -> 0 | F32: =$C$32 -> 0 | G32: =$C$32 -> 0 | H32: =$C$32 -> 0 | I32: =$C$32 -> 0 | J32: =$C$32 -> 0 | K32: =$C$32 -> 0 | ... N32: =$C$32 -> 0 | O32: =SUM(C32:N32) -> 0 | P32: =IFERROR(O32/12,"") -> 0 | Q32: ← Tab 1 · Perfil | más importante — fondo amarillo
B33: Seguro de propiedad | C33: 0 | D33: =$C$33 -> 0 | E33: =$C$33 -> 0 | F33: =$C$33 -> 0 | G33: =$C$33 -> 0 | H33: =$C$33 -> 0 | I33: =$C$33 -> 0 | J33: =$C$33 -> 0 | K33: =$C$33 -> 0 | ... N33: =$C$33 -> 0 | O33: =SUM(C33:N33) -> 0 | P33: =IFERROR(O33/12,"") -> 0 | Q33: Prorateado mensual
B34: Impuesto de la propiedad (prorateado mensual) | C34: 0 | O34: =SUM(C34:N34) -> 0 | P34: =IFERROR(O34/12,"") -> 0
B35: Internet de alta velocidad | C35: 0 | D35: =$C$35 -> 0 | E35: =$C$35 -> 0 | F35: =$C$35 -> 0 | G35: =$C$35 -> 0 | H35: =$C$35 -> 0 | I35: =$C$35 -> 0 | J35: =$C$35 -> 0 | K35: =$C$35 -> 0 | ... N35: =$C$35 -> 0 | O35: =SUM(C35:N35) -> 0 | P35: =IFERROR(O35/12,"") -> 0
B36: (agregar concepto) | C36: =IFERROR(C8*'1. Perfil'!C25,0) -> 0 | D36: =$C$36 -> 0 | E36: =$C$36 -> 0 | F36: =$C$36 -> 0 | G36: =$C$36 -> 0 | H36: =$C$36 -> 0 | I36: =$C$36 -> 0 | J36: =$C$36 -> 0 | K36: =$C$36 -> 0 | ... N36: =$C$36 -> 0 | O36: =SUM(C36:N36) -> 0 | P36: =IFERROR(O36/12,"") -> 0 | Q36: 👉 Espacios libres — agrega aquí cualquier concepto extra a tu discreción
B37: (agregar concepto) | D37: =$C$37 -> 0 | E37: =$C$37 -> 0 | F37: =$C$37 -> 0 | G37: =$C$37 -> 0 | H37: =$C$37 -> 0 | I37: =$C$37 -> 0 | J37: =$C$37 -> 0 | K37: =$C$37 -> 0 | ... N37: =$C$37 -> 0 | O37: =SUM(C37:N37) -> 0 | P37: =IFERROR(O37/12,"") -> 0
B38: (agregar concepto) | D38: =$C$38 -> 0 | E38: =$C$38 -> 0 | F38: =$C$38 -> 0 | G38: =$C$38 -> 0 | H38: =$C$38 -> 0 | I38: =$C$38 -> 0 | J38: =$C$38 -> 0 | K38: =$C$38 -> 0 | ... N38: =$C$38 -> 0 | O38: =SUM(C38:N38) -> 0 | P38: =IFERROR(O38/12,"") -> 0
B39: Comisión plataforma (Airbnb) | C39: =IFERROR(C8*'1. Perfil'!C25,0) -> 0 | D39: =IFERROR(D8*'1. Perfil'!C25,0) -> 0 | E39: =IFERROR(E8*'1. Perfil'!C25,0) -> 0 | F39: =IFERROR(F8*'1. Perfil'!C25,0) -> 0 | G39: =IFERROR(G8*'1. Perfil'!C25,0) -> 0 | H39: =IFERROR(H8*'1. Perfil'!C25,0) -> 0 | I39: =IFERROR(I8*'1. Perfil'!C25,0) -> 0 | J39: =IFERROR(J8*'1. Perfil'!C25,0) -> 0 | K39: =IFERROR(K8*'1. Perfil'!C25,0) -> 0 | L39: =IFERROR(L8*'1. Perfil'!C25,0) -> 0 | M39: =IFERROR(M8*'1. Perfil'!C25,0) -> 0 | N39: =IFERROR(N8*'1. Perfil'!C25,0) -> 0 | O39: =SUM(C39:N39) -> 0 | P39: =IFERROR(O39/12,"") -> 0
B40: COSTOS VARIABLES — varían cada mes · ingresa el importe real
...

Sheet 4b. Aspiracional
B1: Cadencia de Reservas™ — Estudio Aspiracional | Potencial según el mercado
B2: Proyección usando los PROMEDIOS del mercado (10 propiedades). Muestra el potencial si igualas al mercado en tarifa y ocupación.
B3: CONCEPTO | C3: Ene | D3: Feb | E3: Mar | F3: Abr | G3: May | H3: Jun | I3: Jul | J3: Ago | K3: Sep | L3: Oct | M3: Nov | N3: Dic | O3: Total anual | P3: Prom. mensual | Q3: Notas / referencia
B4: INGRESOS POTENCIALES — basados en PROMEDIOS del mercado (Tab 2)
B5: Tarifa promedio de mercado (por mes) | C5: =IFERROR('2. Mercado'!M15,"") | D5: =IFERROR('2. Mercado'!N15,"") | E5: =IFERROR('2. Mercado'!O15,"") | F5: =IFERROR('2. Mercado'!P15,"") | G5: =IFERROR('2. Mercado'!Q15,"") | H5: =IFERROR('2. Mercado'!R15,"") | I5: =IFERROR('2. Mercado'!S15,"") | J5: =IFERROR('2. Mercado'!T15,"") | ... N5: =IFERROR('2. Mercado'!X15,"") | O5: =IFERROR(AVERAGE(C5:N5),"") | P5: ← promedio anual | Q5: ← desde Tab 2 · Mercado — promedio de 10 propiedades
B6: Ocupación estimada % (mensual) | C6: =IFERROR('2. Mercado'!$Z$15,"") | D6: =IFERROR('2. Mercado'!$Z$15,"") | E6: =IFERROR('2. Mercado'!$Z$15,"") | F6: =IFERROR('2. Mercado'!$Z$15,"") | G6: =IFERROR('2. Mercado'!$Z$15,"") | H6: =IFERROR('2. Mercado'!$Z$15,"") | I6: =IFERROR('2. Mercado'!$Z$15,"") | J6: =IFERROR('2. Mercado'!$Z$15,"") | ... N6: =IFERROR('2. Mercado'!$Z$15,"") | O6: =IFERROR(AVERAGE(C6:N6),"") | P6: ← promedio anual | Q6: ← Tab 2 · puedes sobreescribir mes a mes con dato de AirDNA
B7: Días del mes | C7: 31 | D7: 28 | E7: 31 | F7: 30 | G7: 31 | H7: 30 | I7: 31 | J7: 31 | K7: 30 | L7: 31 | M7: 30 | N7: 31 | O7: 365 | P7: =O7/12 -> 30.416667 | Q7: Referencia automática
B8: Ingreso por rentas mensual | C8: =IFERROR(C5*C6*C7,0) -> 0 | D8: =IFERROR(D5*D6*D7,0) -> 0 | E8: =IFERROR(E5*E6*E7,0) -> 0 | F8: =IFERROR(F5*F6*F7,0) -> 0 | G8: =IFERROR(G5*G6*G7,0) -> 0 | H8: =IFERROR(H5*H6*H7,0) -> 0 | I8: =IFERROR(I5*I6*I7,0) -> 0 | J8: =IFERROR(J5*J6*J7,0) -> 0 | ... N8: =IFERROR(N5*N6*N7,0) -> 0 | O8: =SUM(C8:N8) -> 0 | P8: =IFERROR(O8/12,"") -> 0 | Q8: tarifa * ocupación * días del mes
B9: Tarifa de limpieza | C9: =IFERROR('1. Perfil'!C23,0) -> 0 | D9: =IFERROR('1. Perfil'!C23,0) -> 0 | E9: =IFERROR('1. Perfil'!C23,0) -> 0 | F9: =IFERROR('1. Perfil'!C23,0) -> 0 | G9: =IFERROR('1. Perfil'!C23,0) -> 0 | H9: =IFERROR('1. Perfil'!C23,0) -> 0 | I9: =IFERROR('1. Perfil'!C23,0) -> 0 | J9: =IFERROR('1. Perfil'!C23,0) -> 0 | K9: =IFERROR('1. Perfil'!C23,0) -> 0 | L9: =IFERROR('1. Perfil'!C23,0) -> 0 | M9: =IFERROR('1. Perfil'!C23,0) -> 0 | N9: =IFERROR('1. Perfil'!C23,0) -> 0 | O9: =IFERROR('1. Perfil'!C23,0) -> 0 | P9: tarifa fija | Q9: ← desde Tab 1 · Perfil
B10: Limpiezas estimadas por mes | C10: =IFERROR('4a. Factibilidad'!C10,0) -> 0 | D10: =IFERROR('4a. Factibilidad'!D10,0) -> 0 | E10: =IFERROR('4a. Factibilidad'!E10,0) -> 0 | F10: =IFERROR('4a. Factibilidad'!F10,0) -> 0 | G10: =IFERROR('4a. Factibilidad'!G10,0) -> 0 | H10: =IFERROR('4a. Factibilidad'!H10,0) -> 0 | I10: =IFERROR('4a. Factibilidad'!I10,0) -> 0 | J10: =IFERROR('4a. Factibilidad'!J10,0) -> 0 | ... N10: =IFERROR('4a. Factibilidad'!N10,0) -> 0 | O10: =SUM(C10:N10) -> 0 | P10: =IFERROR(O10/12,"") -> 0 | Q10: Ingresa el número de limpiezas por mes
B11: Ingreso por limpiezas (informativo — no se suma) | C11: =IFERROR(C9*C10,0) -> 0 | D11: =IFERROR(D9*D10,0) -> 0 | E11: =IFERROR(E9*E10,0) -> 0 | F11: =IFERROR(F9*F10,0) -> 0 | G11: =IFERROR(G9*G10,0) -> 0 | H11: =IFERROR(H9*H10,0) -> 0 | I11: =IFERROR(I9*I10,0) -> 0 | J11: =IFERROR(J9*J10,0) -> 0 | ... N11: =IFERROR(N9*N10,0) -> 0 | O11: =SUM(C11:N11) -> 0 | P11: =IFERROR(O11/12,"") -> 0 | Q11: Solo visual: la limpieza ya viene incluida en el ingreso por rentas
B12: INGRESO TOTAL MENSUAL | C12: =C8 -> 0 | D12: =D8 -> 0 | E12: =E8 -> 0 | F12: =F8 -> 0 | G12: =G8 -> 0 | H12: =H8 -> 0 | I12: =I8 -> 0 | J12: =J8 -> 0 | ... N12: =N8 -> 0 | O12: =SUM(C12:N12) -> 0 | P12: =IFERROR(O12/12,"") -> 0
B13: COSTOS DE OPERACIÓN — ingresa el gasto real de cada mes
B14: Camarista / servicio de limpieza | C14: =IFERROR('4a. Factibilidad'!C14,0) -> 0 | D14: =IFERROR('4a. Factibilidad'!D14,0) -> 0 | E14: =IFERROR('4a. Factibilidad'!E14,0) -> 0 | F14: =IFERROR('4a. Factibilidad'!F14,0) -> 0 | G14: =IFERROR('4a. Factibilidad'!G14,0) -> 0 | H14: =IFERROR('4a. Factibilidad'!H14,0) -> 0 | I14: =IFERROR('4a. Factibilidad'!I14,0) -> 0 | J14: =IFERROR('4a. Factibilidad'!J14,0) -> 0 | ... N14: =IFERROR('4a. Factibilidad'!N14,0) -> 0 | O14: =SUM(C14:N14) -> 0 | P14: =IFERROR(O14/12,"") -> 0 | Q14: Por rotación o mensual fijo
B15: Mantenimiento general (persona) | C15: =IFERROR('4a. Factibilidad'!C15,0) -> 0 | D15: =IFERROR('4a. Factibilidad'!D15,0) -> 0 | E15: =IFERROR('4a. Factibilidad'!E15,0) -> 0 | F15: =IFERROR('4a. Factibilidad'!F15,0) -> 0 | G15: =IFERROR('4a. Factibilidad'!G15,0) -> 0 | H15: =IFERROR('4a. Factibilidad'!H15,0) -> 0 | I15: =IFERROR('4a. Factibilidad'!I15,0) -> 0 | J15: =IFERROR('4a. Factibilidad'!J15,0) -> 0 | ... N15: =IFERROR('4a. Factibilidad'!N15,0) -> 0 | O15: =SUM(C15:N15) -> 0 | P15: =IFERROR(O15/12,"") -> 0
B16: Insumos de limpieza | C16: =IFERROR('4a. Factibilidad'!C16,0) -> 0 | D16: =IFERROR('4a. Factibilidad'!D16,0) -> 0 | E16: =IFERROR('4a. Factibilidad'!E16,0) -> 0 | F16: =IFERROR('4a. Factibilidad'!F16,0) -> 0 | G16: =IFERROR('4a. Factibilidad'!G16,0) -> 0 | H16: =IFERROR('4a. Factibilidad'!H16,0) -> 0 | I16: =IFERROR('4a. Factibilidad'!I16,0) -> 0 | J16: =IFERROR('4a. Factibilidad'!J16,0) -> 0 | ... N16: =IFERROR('4a. Factibilidad'!N16,0) -> 0 | O16: =SUM(C16:N16) -> 0 | P16: =IFERROR(O16/12,"") -> 0
B17: Insumos de mantenimiento | C17: =IFERROR('4a. Factibilidad'!C17,0) -> 0 | D17: =IFERROR('4a. Factibilidad'!D17,0) -> 0 | E17: =IFERROR('4a. Factibilidad'!E17,0) -> 0 | F17: =IFERROR('4a. Factibilidad'!F17,0) -> 0 | G17: =IFERROR('4a. Factibilidad'!G17,0) -> 0 | H17: =IFERROR('4a. Factibilidad'!H17,0) -> 0 | I17: =IFERROR('4a. Factibilidad'!I17,0) -> 0 | J17: =IFERROR('4a. Factibilidad'!J17,0) -> 0 | ... N17: =IFERROR('4a. Factibilidad'!N17,0) -> 0 | O17: =SUM(C17:N17) -> 0 | P17: =IFERROR(O17/12,"") -> 0
B18: ='4a. Factibilidad'!B18 -> (agregar concepto) | C18: =IFERROR('4a. Factibilidad'!C18,0) -> 0 | D18: =IFERROR('4a. Factibilidad'!D18,0) -> 0 | E18: =IFERROR('4a. Factibilidad'!E18,0) -> 0 | F18: =IFERROR('4a. Factibilidad'!F18,0) -> 0 | G18: =IFERROR('4a. Factibilidad'!G18,0) -> 0 | H18: =IFERROR('4a. Factibilidad'!H18,0) -> 0 | I18: =IFERROR('4a. Factibilidad'!I18,0) -> 0 | J18: =IFERROR('4a. Factibilidad'!J18,0) -> 0 | ... N18: =IFERROR('4a. Factibilidad'!N18,0) -> 0 | O18: =SUM(C18:N18) -> 0 | P18: =IFERROR(O18/12,"") -> 0
B19: ='4a. Factibilidad'!B19 -> (agregar concepto) | C19: =IFERROR('4a. Factibilidad'!C19,0) -> 0 | D19: =IFERROR('4a. Factibilidad'!D19,0) -> 0 | E19: =IFERROR('4a. Factibilidad'!E19,0) -> 0 | F19: =IFERROR('4a. Factibilidad'!F19,0) -> 0 | G19: =IFERROR('4a. Factibilidad'!G19,0) -> 0 | H19: =IFERROR('4a. Factibilidad'!H19,0) -> 0 | I19: =IFERROR('4a. Factibilidad'!I19,0) -> 0 | J19: =IFERROR('4a. Factibilidad'!J19,0) -> 0 | ... N19: =IFERROR('4a. Factibilidad'!N19,0) -> 0 | O19: =SUM(C19:N19) -> 0 | P19: =IFERROR(O19/12,"") -> 0
B20: ='4a. Factibilidad'!B20 -> (agregar concepto) | C20: =IFERROR('4a. Factibilidad'!C20,0) -> 0 | D20: =IFERROR('4a. Factibilidad'!D20,0) -> 0 | E20: =IFERROR('4a. Factibilidad'!E20,0) -> 0 | F20: =IFERROR('4a. Factibilidad'!F20,0) -> 0 | G20: =IFERROR('4a. Factibilidad'!G20,0) -> 0 | H20: =IFERROR('4a. Factibilidad'!H20,0) -> 0 | I20: =IFERROR('4a. Factibilidad'!I20,0) -> 0 | J20: =IFERROR('4a. Factibilidad'!J20,0) -> 0 | ... N20: =IFERROR('4a. Factibilidad'!N20,0) -> 0 | O20: =SUM(C20:N20) -> 0 | P20: =IFERROR(O20/12,"") -> 0
B21: MANTENIMIENTO DE EQUIPOS — celdas amarillas = meses sugeridos
B22: Aire acondicionado | C22: =IFERROR('4a. Factibilidad'!C22,0) -> 0 | D22: =IFERROR('4a. Factibilidad'!D22,0) -> 0 | E22: =IFERROR('4a. Factibilidad'!E22,0) -> 0 | F22: =IFERROR('4a. Factibilidad'!F22,0) -> 0 | G22: =IFERROR('4a. Factibilidad'!G22,0) -> 0 | H22: =IFERROR('4a. Factibilidad'!H22,0) -> 0 | I22: =IFERROR('4a. Factibilidad'!I22,0) -> 0 | J22: =IFERROR('4a. Factibilidad'!J22,0) -> 0 | ... N22: =IFERROR('4a. Factibilidad'!N22,0) -> 0 | O22: =SUM(C22:N22) -> 0 | P22: =IFERROR(O22/12,"") -> 0 | Q22: Sugerido: Jun y Dic · proratea el costo semestral
B23: Alberca / jacuzzi | C23: =IFERROR('4a. Factibilidad'!C23,0) -> 0 | D23: =IFERROR('4a. Factibilidad'!D23,0) -> 0 | E23: =IFERROR('4a. Factibilidad'!E23,0) -> 0 | F23: =IFERROR('4a. Factibilidad'!F23,0) -> 0 | G23: =IFERROR('4a. Factibilidad'!G23,0) -> 0 | H23: =IFERROR('4a. Factibilidad'!H23,0) -> 0 | I23: =IFERROR('4a. Factibilidad'!I23,0) -> 0 | J23: =IFERROR('4a. Factibilidad'!J23,0) -> 0 | ... N23: =IFERROR('4a. Factibilidad'!N23,0) -> 0 | O23: =SUM(C23:N23) -> 0 | P23: =IFERROR(O23/12,"") -> 0 | Q23: Mantenimiento semanal o quincenal
B24: Electrodomésticos (refri, lavadora…) | C24: =IFERROR('4a. Factibilidad'!C24,0) -> 0 | D24: =IFERROR('4a. Factibilidad'!D24,0) -> 0 | E24: =IFERROR('4a. Factibilidad'!E24,0) -> 0 | F24: =IFERROR('4a. Factibilidad'!F24,0) -> 0 | G24: =IFERROR('4a. Factibilidad'!G24,0) -> 0 | H24: =IFERROR('4a. Factibilidad'!H24,0) -> 0 | I24: =IFERROR('4a. Factibilidad'!I24,0) -> 0 | J24: =IFERROR('4a. Factibilidad'!J24,0) -> 0 | ... N24: =IFERROR('4a. Factibilidad'!N24,0) -> 0 | O24: =SUM(C24:N24) -> 0 | P24: =IFERROR(O24/12,"") -> 0 | Q24: Garantías, contratos preventivos
B25: Fumigación | C25: =IFERROR('4a. Factibilidad'!C25,0) -> 0 | D25: =IFERROR('4a. Factibilidad'!D25,0) -> 0 | E25: =IFERROR('4a. Factibilidad'!E25,0) -> 0 | F25: =IFERROR('4a. Factibilidad'!F25,0) -> 0 | G25: =IFERROR('4a. Factibilidad'!G25,0) -> 0 | H25: =IFERROR('4a. Factibilidad'!H25,0) -> 0 | I25: =IFERROR('4a. Factibilidad'!I25,0) -> 0 | J25: =IFERROR('4a. Factibilidad'!J25,0) -> 0 | ... N25: =IFERROR('4a. Factibilidad'!N25,0) -> 0 | O25: =SUM(C25:N25) -> 0 | P25: =IFERROR(O25/12,"") -> 0 | Q25: Sugerido: Mar, Jun, Sep, Dic (trimestral)
B26: Jardinería / paneles solares | C26: =IFERROR('4a. Factibilidad'!C26,0) -> 0 | D26: =IFERROR('4a. Factibilidad'!D26,0) -> 0 | E26: =IFERROR('4a. Factibilidad'!E26,0) -> 0 | F26: =IFERROR('4a. Factibilidad'!F26,0) -> 0 | G26: =IFERROR('4a. Factibilidad'!G26,0) -> 0 | H26: =IFERROR('4a. Factibilidad'!H26,0) -> 0 | I26: =IFERROR('4a. Factibilidad'!I26,0) -> 0 | J26: =IFERROR('4a. Factibilidad'!J26,0) -> 0 | ... N26: =IFERROR('4a. Factibilidad'!N26,0) -> 0 | O26: =SUM(C26:N26) -> 0 | P26: =IFERROR(O26/12,"") -> 0
B27: Mantenimiento general extra | C27: =IFERROR('4a. Factibilidad'!C27,0) -> 0 | D27: =IFERROR('4a. Factibilidad'!D27,0) -> 0 | E27: =IFERROR('4a. Factibilidad'!E27,0) -> 0 | F27: =IFERROR('4a. Factibilidad'!F27,0) -> 0 | G27: =IFERROR('4a. Factibilidad'!G27,0) -> 0 | H27: =IFERROR('4a. Factibilidad'!H27,0) -> 0 | I27: =IFERROR('4a. Factibilidad'!I27,0) -> 0 | J27: =IFERROR('4a. Factibilidad'!J27,0) -> 0 | ... N27: =IFERROR('4a. Factibilidad'!N27,0) -> 0 | O27: =SUM(C27:N27) -> 0 | P27: =IFERROR(O27/12,"") -> 0 | Q27: Reparaciones menores imprevistas
B28: ='4a. Factibilidad'!B28 -> (agregar concepto) | C28: =IFERROR('4a. Factibilidad'!C28,0) -> 0 | D28: =IFERROR('4a. Factibilidad'!D28,0) -> 0 | E28: =IFERROR('4a. Factibilidad'!E28,0) -> 0 | F28: =IFERROR('4a. Factibilidad'!F28,0) -> 0 | G28: =IFERROR('4a. Factibilidad'!G28,0) -> 0 | H28: =IFERROR('4a. Factibilidad'!H28,0) -> 0 | I28: =IFERROR('4a. Factibilidad'!I28,0) -> 0 | J28: =IFERROR('4a. Factibilidad'!J28,0) -> 0 | ... N28: =IFERROR('4a. Factibilidad'!N28,0) -> 0 | O28: =SUM(C28:N28) -> 0 | P28: =IFERROR(O28/12,"") -> 0
B29: ='4a. Factibilidad'!B29 -> (agregar concepto) | C29: =IFERROR('4a. Factibilidad'!C29,0) -> 0 | D29: =IFERROR('4a. Factibilidad'!D29,0) -> 0 | E29: =IFERROR('4a. Factibilidad'!E29,0) -> 0 | F29: =IFERROR('4a. Factibilidad'!F29,0) -> 0 | G29: =IFERROR('4a. Factibilidad'!G29,0) -> 0 | H29: =IFERROR('4a. Factibilidad'!H29,0) -> 0 | I29: =IFERROR('4a. Factibilidad'!I29,0) -> 0 | J29: =IFERROR('4a. Factibilidad'!J29,0) -> 0 | ... N29: =IFERROR('4a. Factibilidad'!N29,0) -> 0 | O29: =SUM(C29:N29) -> 0 | P29: =IFERROR(O29/12,"") -> 0
B30: ='4a. Factibilidad'!B30 -> (agregar concepto) | C30: =IFERROR('4a. Factibilidad'!C30,0) -> 0 | D30: =IFERROR('4a. Factibilidad'!D30,0) -> 0 | E30: =IFERROR('4a. Factibilidad'!E30,0) -> 0 | F30: =IFERROR('4a. Factibilidad'!F30,0) -> 0 | G30: =IFERROR('4a. Factibilidad'!G30,0) -> 0 | H30: =IFERROR('4a. Factibilidad'!H30,0) -> 0 | I30: =IFERROR('4a. Factibilidad'!I30,0) -> 0 | J30: =IFERROR('4a. Factibilidad'!J30,0) -> 0 | ... N30: =IFERROR('4a. Factibilidad'!N30,0) -> 0 | O30: =SUM(C30:N30) -> 0 | P30: =IFERROR(O30/12,"") -> 0
B31: COSTOS FIJOS — escribe solo en Enero · los demás meses se repiten solos
B32: Hipoteca o renta del inmueble | C32: =IFERROR('4a. Factibilidad'!C32,0) -> 0 | D32: =$C$32 -> 0 | E32: =$C$32 -> 0 | F32: =$C$32 -> 0 | G32: =$C$32 -> 0 | H32: =$C$32 -> 0 | I32: =$C$32 -> 0 | J32: =$C$32 -> 0 | K32: =$C$32 -> 0 | ... N32: =$C$32 -> 0 | O32: =SUM(C32:N32) -> 0 | P32: =IFERROR(O32/12,"") -> 0 | Q32: ← Tab 1 · Perfil | más importante — fondo amarillo
B33: Seguro de propiedad | C33: =IFERROR('4a. Factibilidad'!C33,0) -> 0 | D33: =IFERROR('4a. Factibilidad'!D33,0) -> 0 | E33: =IFERROR('4a. Factibilidad'!E33,0) -> 0 | F33: =IFERROR('4a. Factibilidad'!F33,0) -> 0 | G33: =IFERROR('4a. Factibilidad'!G33,0) -> 0 | H33: =IFERROR('4a. Factibilidad'!H33,0) -> 0 | I33: =IFERROR('4a. Factibilidad'!I33,0) -> 0 | J33: =IFERROR('4a. Factibilidad'!J33,0) -> 0 | ... N33: =IFERROR('4a. Factibilidad'!N33,0) -> 0 | O33: =SUM(C33:N33) -> 0 | P33: =IFERROR(O33/12,"") -> 0 | Q33: Prorateado mensual
B34: Predial (prorateado mensual) | C34: =IFERROR('4a. Factibilidad'!C34,0) -> 0 | D34: =IFERROR('4a. Factibilidad'!D34,0) -> 0 | E34: =IFERROR('4a. Factibilidad'!E34,0) -> 0 | F34: =IFERROR('4a. Factibilidad'!F34,0) -> 0 | G34: =IFERROR('4a. Factibilidad'!G34,0) -> 0 | H34: =IFERROR('4a. Factibilidad'!H34,0) -> 0 | I34: =IFERROR('4a. Factibilidad'!I34,0) -> 0 | J34: =IFERROR('4a. Factibilidad'!J34,0) -> 0 | ... N34: =IFERROR('4a. Factibilidad'!N34,0) -> 0 | O34: =SUM(C34:N34) -> 0 | P34: =IFERROR(O34/12,"") -> 0
B35: Internet de alta velocidad | C35: 0 | D35: =$C$35 -> 0 | E35: =$C$35 -> 0 | F35: =$C$35 -> 0 | G35: =$C$35 -> 0 | H35: =$C$35 -> 0 | I35: =$C$35 -> 0 | J35: =$C$35 -> 0 | K35: =$C$35 -> 0 | ... N35: =$C$35 -> 0 | O35: =SUM(C35:N35) -> 0 | P35: =IFERROR(O35/12,"") -> 0
B36: ='4a. Factibilidad'!B36 -> (agregar concepto) | C36: =IFERROR('4a. Factibilidad'!C36,0) -> 0 | D36: =IFERROR('4a. Factibilidad'!D36,0) -> 0 | E36: =IFERROR('4a. Factibilidad'!E36,0) -> 0 | F36: =IFERROR('4a. Factibilidad'!F36,0) -> 0 | G36: =IFERROR('4a. Factibilidad'!G36,0) -> 0 | H36: =IFERROR('4a. Factibilidad'!H36,0) -> 0 | I36: =IFERROR('4a. Factibilidad'!I36,0) -> 0 | J36: =IFERROR('4a. Factibilidad'!J36,0) -> 0 | ... N36: =IFERROR('4a. Factibilidad'!N36,0) -> 0 | O36: =SUM(C36:N36) -> 0 | P36: =IFERROR(O36/12,"") -> 0
B37: ='4a. Factibilidad'!B37 -> (agregar concepto) | C37: =IFERROR('4a. Factibilidad'!C37,0) -> 0 | D37: =IFERROR('4a. Factibilidad'!D37,0) -> 0 | E37: =IFERROR('4a. Factibilidad'!E37,0) -> 0 | F37: =IFERROR('4a. Factibilidad'!F37,0) -> 0 | G37: =IFERROR('4a. Factibilidad'!G37,0) -> 0 | H37: =IFERROR('4a. Factibilidad'!H37,0) -> 0 | I37: =IFERROR('4a. Factibilidad'!I37,0) -> 0 | J37: =IFERROR('4a. Factibilidad'!J37,0) -> 0 | ... N37: =IFERROR('4a. Factibilidad'!N37,0) -> 0 | O37: =SUM(C37:N37) -> 0 | P37: =IFERROR(O37/12,"") -> 0
B38: ='4a. Factibilidad'!B38 -> (agregar concepto) | C38: =IFERROR('4a. Factibilidad'!C38,0) -> 0 | D38: =IFERROR('4a. Factibilidad'!D38,0) -> 0 | E38: =IFERROR('4a. Factibilidad'!E38,0) -> 0 | F38: =IFERROR('4a. Factibilidad'!F38,0) -> 0 | G38: =IFERROR('4a. Factibilidad'!G38,0) -> 0 | H38: =IFERROR('4a. Factibilidad'!H38,0) -> 0 | I38: =IFERROR('4a. Factibilidad'!I38,0) -> 0 | J38: =IFERROR('4a. Factibilidad'!J38,0) -> 0 | ... N38: =IFERROR('4a. Factibilidad'!N38,0) -> 0 | O38: =SUM(C38:N38) -> 0 | P38: =IFERROR(O38/12,"") -> 0
B39: ='4a. Factibilidad'!B39 -> Comisión plataforma (Airbnb) | C39: =IFERROR('4a. Factibilidad'!C39,0) -> 0 | D39: =IFERROR('4a. Factibilidad'!D39,0) -> 0 | E39: =IFERROR('4a. Factibilidad'!E39,0) -> 0 | F39: =IFERROR('4a. Factibilidad'!F39,0) -> 0 | G39: =IFERROR('4a. Factibilidad'!G39,0) -> 0 | H39: =IFERROR('4a. Factibilidad'!H39,0) -> 0 | I39: =IFERROR('4a. Factibilidad'!I39,0) -> 0 | J39: =IFERROR('4a. Factibilidad'!J39,0) -> 0 | ... N39: =IFERROR('4a. Factibilidad'!N39,0) -> 0 | O39: =SUM(C39:N39) -> 0 | P39: =IFERROR(O39/12,"") -> 0
B40: COSTOS VARIABLES — varían cada mes · ingresa el importe real
...

Sheet 4c. Techo de Mercado
B1: Cadencia de Reservas™ — Techo de Mercado | Factibilidad con Top Propiedades
B2: Escenario máximo: usa la tarifa promedio y ocupación de las TOP 5 propiedades (Tab 3). Muestra el potencial máximo si lograras igualar a las mejores propiedades de tu zona.
B3: CONCEPTO | C3: Ene | D3: Feb | E3: Mar | F3: Abr | G3: May | H3: Jun | I3: Jul | J3: Ago | K3: Sep | L3: Oct | M3: Nov | N3: Dic | O3: Total anual | P3: Prom. mensual | Q3: Notas / referencia
B4: INGRESOS ESTIMADOS — provienen del Estudio de Mercado (Tab 2)
B5: Tarifa promedio de mercado (por mes) | C5: =IFERROR(AVERAGE('3. Top Propiedades'!$L$5:$L$9),0) -> 0 | D5: =IFERROR(AVERAGE('3. Top Propiedades'!$L$5:$L$9),0) -> 0 | E5: =IFERROR(AVERAGE('3. Top Propiedades'!$L$5:$L$9),0) -> 0 | F5: =IFERROR(AVERAGE('3. Top Propiedades'!$L$5:$L$9),0) -> 0 | G5: =IFERROR(AVERAGE('3. Top Propiedades'!$L$5:$L$9),0) -> 0 | H5: =IFERROR(AVERAGE('3. Top Propiedades'!$L$5:$L$9),0) -> 0 | I5: =IFERROR(AVERAGE('3. Top Propiedades'!$L$5:$L$9),0) -> 0 | J5: =IFERROR(AVERAGE('3. Top Propiedades'!$L$5:$L$9),0) -> 0 | ... N5: =IFERROR(AVERAGE('3. Top Propiedades'!$L$5:$L$9),0) -> 0 | O5: =IFERROR(AVERAGE(C5:N5),"") -> 0 | P5: ← promedio anual | Q5: ← Promedio ADR de Top 5 propiedades (Tab 3)
B6: Ocupación estimada % (mensual) | C6: =IFERROR(AVERAGE('3. Top Propiedades'!$M$5:$M$9),0) -> 0 | D6: =IFERROR(AVERAGE('3. Top Propiedades'!$M$5:$M$9),0) -> 0 | E6: =IFERROR(AVERAGE('3. Top Propiedades'!$M$5:$M$9),0) -> 0 | F6: =IFERROR(AVERAGE('3. Top Propiedades'!$M$5:$M$9),0) -> 0 | G6: =IFERROR(AVERAGE('3. Top Propiedades'!$M$5:$M$9),0) -> 0 | H6: =IFERROR(AVERAGE('3. Top Propiedades'!$M$5:$M$9),0) -> 0 | I6: =IFERROR(AVERAGE('3. Top Propiedades'!$M$5:$M$9),0) -> 0 | J6: =IFERROR(AVERAGE('3. Top Propiedades'!$M$5:$M$9),0) -> 0 | ... N6: =IFERROR(AVERAGE('3. Top Propiedades'!$M$5:$M$9),0) -> 0 | O6: =IFERROR(AVERAGE(C6:N6),"") -> 0 | P6: ← promedio anual | Q6: ← Promedio ocupación de Top 5 propiedades (Tab 3)
B7: Días del mes | C7: 31 | D7: 28 | E7: 31 | F7: 30 | G7: 31 | H7: 30 | I7: 31 | J7: 31 | K7: 30 | L7: 31 | M7: 30 | N7: 31 | O7: 365 | P7: =O7/12 -> 30.416667 | Q7: Referencia automática
B8: Ingreso por rentas mensual | C8: =IFERROR(C5*C6*C7,0) -> 0 | D8: =IFERROR(D5*D6*D7,0) -> 0 | E8: =IFERROR(E5*E6*E7,0) -> 0 | F8: =IFERROR(F5*F6*F7,0) -> 0 | G8: =IFERROR(G5*G6*G7,0) -> 0 | H8: =IFERROR(H5*H6*H7,0) -> 0 | I8: =IFERROR(I5*I6*I7,0) -> 0 | J8: =IFERROR(J5*J6*J7,0) -> 0 | ... N8: =IFERROR(N5*N6*N7,0) -> 0 | O8: =SUM(C8:N8) -> 0 | P8: =IFERROR(O8/12,"") -> 0 | Q8: tarifa * ocupación * días del mes
B9: Tarifa de limpieza | C9: =IFERROR('1. Perfil'!C23,0) -> 0 | D9: =IFERROR('1. Perfil'!C23,0) -> 0 | E9: =IFERROR('1. Perfil'!C23,0) -> 0 | F9: =IFERROR('1. Perfil'!C23,0) -> 0 | G9: =IFERROR('1. Perfil'!C23,0) -> 0 | H9: =IFERROR('1. Perfil'!C23,0) -> 0 | I9: =IFERROR('1. Perfil'!C23,0) -> 0 | J9: =IFERROR('1. Perfil'!C23,0) -> 0 | K9: =IFERROR('1. Perfil'!C23,0) -> 0 | L9: =IFERROR('1. Perfil'!C23,0) -> 0 | M9: =IFERROR('1. Perfil'!C23,0) -> 0 | N9: =IFERROR('1. Perfil'!C23,0) -> 0 | O9: =IFERROR('1. Perfil'!C23,0) -> 0 | P9: tarifa fija | Q9: ← desde Tab 1 · Perfil
B10: Limpiezas estimadas por mes | C10: =IFERROR('4a. Factibilidad'!C10,0) -> 0 | D10: =IFERROR('4a. Factibilidad'!D10,0) -> 0 | E10: =IFERROR('4a. Factibilidad'!E10,0) -> 0 | F10: =IFERROR('4a. Factibilidad'!F10,0) -> 0 | G10: =IFERROR('4a. Factibilidad'!G10,0) -> 0 | H10: =IFERROR('4a. Factibilidad'!H10,0) -> 0 | I10: =IFERROR('4a. Factibilidad'!I10,0) -> 0 | J10: =IFERROR('4a. Factibilidad'!J10,0) -> 0 | ... N10: =IFERROR('4a. Factibilidad'!N10,0) -> 0 | O10: =SUM(C10:N10) -> 0 | P10: =IFERROR(O10/12,"") -> 0 | Q10: Ingresa el número de limpiezas por mes
B11: Ingreso por limpiezas (informativo — no se suma) | C11: =IFERROR(C9*C10,0) -> 0 | D11: =IFERROR(D9*D10,0) -> 0 | E11: =IFERROR(E9*E10,0) -> 0 | F11: =IFERROR(F9*F10,0) -> 0 | G11: =IFERROR(G9*G10,0) -> 0 | H11: =IFERROR(H9*H10,0) -> 0 | I11: =IFERROR(I9*I10,0) -> 0 | J11: =IFERROR(J9*J10,0) -> 0 | ... N11: =IFERROR(N9*N10,0) -> 0 | O11: =SUM(C11:N11) -> 0 | P11: =IFERROR(O11/12,"") -> 0 | Q11: Solo visual: la limpieza ya viene incluida en el ingreso por rentas
B12: INGRESO TOTAL MENSUAL | C12: =C8 -> 0 | D12: =D8 -> 0 | E12: =E8 -> 0 | F12: =F8 -> 0 | G12: =G8 -> 0 | H12: =H8 -> 0 | I12: =I8 -> 0 | J12: =J8 -> 0 | ... N12: =N8 -> 0 | O12: =SUM(C12:N12) -> 0 | P12: =IFERROR(O12/12,"") -> 0
B13: COSTOS DE OPERACIÓN — ingresa el gasto real de cada mes
B14: Camarista / servicio de limpieza | C14: =IFERROR('4a. Factibilidad'!C14,0) -> 0 | D14: =IFERROR('4a. Factibilidad'!D14,0) -> 0 | E14: =IFERROR('4a. Factibilidad'!E14,0) -> 0 | F14: =IFERROR('4a. Factibilidad'!F14,0) -> 0 | G14: =IFERROR('4a. Factibilidad'!G14,0) -> 0 | H14: =IFERROR('4a. Factibilidad'!H14,0) -> 0 | I14: =IFERROR('4a. Factibilidad'!I14,0) -> 0 | J14: =IFERROR('4a. Factibilidad'!J14,0) -> 0 | ... N14: =IFERROR('4a. Factibilidad'!N14,0) -> 0 | O14: =SUM(C14:N14) -> 0 | P14: =IFERROR(O14/12,"") -> 0 | Q14: Por rotación o mensual fijo
B15: Mantenimiento general (persona) | C15: =IFERROR('4a. Factibilidad'!C15,0) -> 0 | D15: =IFERROR('4a. Factibilidad'!D15,0) -> 0 | E15: =IFERROR('4a. Factibilidad'!E15,0) -> 0 | F15: =IFERROR('4a. Factibilidad'!F15,0) -> 0 | G15: =IFERROR('4a. Factibilidad'!G15,0) -> 0 | H15: =IFERROR('4a. Factibilidad'!H15,0) -> 0 | I15: =IFERROR('4a. Factibilidad'!I15,0) -> 0 | J15: =IFERROR('4a. Factibilidad'!J15,0) -> 0 | ... N15: =IFERROR('4a. Factibilidad'!N15,0) -> 0 | O15: =SUM(C15:N15) -> 0 | P15: =IFERROR(O15/12,"") -> 0
B16: Insumos de limpieza | C16: =IFERROR('4a. Factibilidad'!C16,0) -> 0 | D16: =IFERROR('4a. Factibilidad'!D16,0) -> 0 | E16: =IFERROR('4a. Factibilidad'!E16,0) -> 0 | F16: =IFERROR('4a. Factibilidad'!F16,0) -> 0 | G16: =IFERROR('4a. Factibilidad'!G16,0) -> 0 | H16: =IFERROR('4a. Factibilidad'!H16,0) -> 0 | I16: =IFERROR('4a. Factibilidad'!I16,0) -> 0 | J16: =IFERROR('4a. Factibilidad'!J16,0) -> 0 | ... N16: =IFERROR('4a. Factibilidad'!N16,0) -> 0 | O16: =SUM(C16:N16) -> 0 | P16: =IFERROR(O16/12,"") -> 0
B17: Insumos de mantenimiento | C17: =IFERROR('4a. Factibilidad'!C17,0) -> 0 | D17: =IFERROR('4a. Factibilidad'!D17,0) -> 0 | E17: =IFERROR('4a. Factibilidad'!E17,0) -> 0 | F17: =IFERROR('4a. Factibilidad'!F17,0) -> 0 | G17: =IFERROR('4a. Factibilidad'!G17,0) -> 0 | H17: =IFERROR('4a. Factibilidad'!H17,0) -> 0 | I17: =IFERROR('4a. Factibilidad'!I17,0) -> 0 | J17: =IFERROR('4a. Factibilidad'!J17,0) -> 0 | ... N17: =IFERROR('4a. Factibilidad'!N17,0) -> 0 | O17: =SUM(C17:N17) -> 0 | P17: =IFERROR(O17/12,"") -> 0
B18: ='4a. Factibilidad'!B18 -> (agregar concepto) | C18: =IFERROR('4a. Factibilidad'!C18,0) -> 0 | D18: =IFERROR('4a. Factibilidad'!D18,0) -> 0 | E18: =IFERROR('4a. Factibilidad'!E18,0) -> 0 | F18: =IFERROR('4a. Factibilidad'!F18,0) -> 0 | G18: =IFERROR('4a. Factibilidad'!G18,0) -> 0 | H18: =IFERROR('4a. Factibilidad'!H18,0) -> 0 | I18: =IFERROR('4a. Factibilidad'!I18,0) -> 0 | J18: =IFERROR('4a. Factibilidad'!J18,0) -> 0 | ... N18: =IFERROR('4a. Factibilidad'!N18,0) -> 0 | O18: =SUM(C18:N18) -> 0 | P18: =IFERROR(O18/12,"") -> 0
B19: ='4a. Factibilidad'!B19 -> (agregar concepto) | C19: =IFERROR('4a. Factibilidad'!C19,0) -> 0 | D19: =IFERROR('4a. Factibilidad'!D19,0) -> 0 | E19: =IFERROR('4a. Factibilidad'!E19,0) -> 0 | F19: =IFERROR('4a. Factibilidad'!F19,0) -> 0 | G19: =IFERROR('4a. Factibilidad'!G19,0) -> 0 | H19: =IFERROR('4a. Factibilidad'!H19,0) -> 0 | I19: =IFERROR('4a. Factibilidad'!I19,0) -> 0 | J19: =IFERROR('4a. Factibilidad'!J19,0) -> 0 | ... N19: =IFERROR('4a. Factibilidad'!N19,0) -> 0 | O19: =SUM(C19:N19) -> 0 | P19: =IFERROR(O19/12,"") -> 0
B20: ='4a. Factibilidad'!B20 -> (agregar concepto) | C20: =IFERROR('4a. Factibilidad'!C20,0) -> 0 | D20: =IFERROR('4a. Factibilidad'!D20,0) -> 0 | E20: =IFERROR('4a. Factibilidad'!E20,0) -> 0 | F20: =IFERROR('4a. Factibilidad'!F20,0) -> 0 | G20: =IFERROR('4a. Factibilidad'!G20,0) -> 0 | H20: =IFERROR('4a. Factibilidad'!H20,0) -> 0 | I20: =IFERROR('4a. Factibilidad'!I20,0) -> 0 | J20: =IFERROR('4a. Factibilidad'!J20,0) -> 0 | ... N20: =IFERROR('4a. Factibilidad'!N20,0) -> 0 | O20: =SUM(C20:N20) -> 0 | P20: =IFERROR(O20/12,"") -> 0
B21: MANTENIMIENTO DE EQUIPOS — celdas amarillas = meses sugeridos
B22: Aire acondicionado | C22: =IFERROR('4a. Factibilidad'!C22,0) -> 0 | D22: =IFERROR('4a. Factibilidad'!D22,0) -> 0 | E22: =IFERROR('4a. Factibilidad'!E22,0) -> 0 | F22: =IFERROR('4a. Factibilidad'!F22,0) -> 0 | G22: =IFERROR('4a. Factibilidad'!G22,0) -> 0 | H22: =IFERROR('4a. Factibilidad'!H22,0) -> 0 | I22: =IFERROR('4a. Factibilidad'!I22,0) -> 0 | J22: =IFERROR('4a. Factibilidad'!J22,0) -> 0 | ... N22: =IFERROR('4a. Factibilidad'!N22,0) -> 0 | O22: =SUM(C22:N22) -> 0 | P22: =IFERROR(O22/12,"") -> 0 | Q22: Sugerido: Jun y Dic · proratea el costo semestral
B23: Alberca / jacuzzi | C23: =IFERROR('4a. Factibilidad'!C23,0) -> 0 | D23: =IFERROR('4a. Factibilidad'!D23,0) -> 0 | E23: =IFERROR('4a. Factibilidad'!E23,0) -> 0 | F23: =IFERROR('4a. Factibilidad'!F23,0) -> 0 | G23: =IFERROR('4a. Factibilidad'!G23,0) -> 0 | H23: =IFERROR('4a. Factibilidad'!H23,0) -> 0 | I23: =IFERROR('4a. Factibilidad'!I23,0) -> 0 | J23: =IFERROR('4a. Factibilidad'!J23,0) -> 0 | ... N23: =IFERROR('4a. Factibilidad'!N23,0) -> 0 | O23: =SUM(C23:N23) -> 0 | P23: =IFERROR(O23/12,"") -> 0 | Q23: Mantenimiento semanal o quincenal
B24: Electrodomésticos (refri, lavadora…) | C24: =IFERROR('4a. Factibilidad'!C24,0) -> 0 | D24: =IFERROR('4a. Factibilidad'!D24,0) -> 0 | E24: =IFERROR('4a. Factibilidad'!E24,0) -> 0 | F24: =IFERROR('4a. Factibilidad'!F24,0) -> 0 | G24: =IFERROR('4a. Factibilidad'!G24,0) -> 0 | H24: =IFERROR('4a. Factibilidad'!H24,0) -> 0 | I24: =IFERROR('4a. Factibilidad'!I24,0) -> 0 | J24: =IFERROR('4a. Factibilidad'!J24,0) -> 0 | ... N24: =IFERROR('4a. Factibilidad'!N24,0) -> 0 | O24: =SUM(C24:N24) -> 0 | P24: =IFERROR(O24/12,"") -> 0 | Q24: Garantías, contratos preventivos
B25: Fumigación | C25: =IFERROR('4a. Factibilidad'!C25,0) -> 0 | D25: =IFERROR('4a. Factibilidad'!D25,0) -> 0 | E25: =IFERROR('4a. Factibilidad'!E25,0) -> 0 | F25: =IFERROR('4a. Factibilidad'!F25,0) -> 0 | G25: =IFERROR('4a. Factibilidad'!G25,0) -> 0 | H25: =IFERROR('4a. Factibilidad'!H25,0) -> 0 | I25: =IFERROR('4a. Factibilidad'!I25,0) -> 0 | J25: =IFERROR('4a. Factibilidad'!J25,0) -> 0 | ... N25: =IFERROR('4a. Factibilidad'!N25,0) -> 0 | O25: =SUM(C25:N25) -> 0 | P25: =IFERROR(O25/12,"") -> 0 | Q25: Sugerido: Mar, Jun, Sep, Dic (trimestral)
B26: Jardinería / paneles solares | C26: =IFERROR('4a. Factibilidad'!C26,0) -> 0 | D26: =IFERROR('4a. Factibilidad'!D26,0) -> 0 | E26: =IFERROR('4a. Factibilidad'!E26,0) -> 0 | F26: =IFERROR('4a. Factibilidad'!F26,0) -> 0 | G26: =IFERROR('4a. Factibilidad'!G26,0) -> 0 | H26: =IFERROR('4a. Factibilidad'!H26,0) -> 0 | I26: =IFERROR('4a. Factibilidad'!I26,0) -> 0 | J26: =IFERROR('4a. Factibilidad'!J26,0) -> 0 | ... N26: =IFERROR('4a. Factibilidad'!N26,0) -> 0 | O26: =SUM(C26:N26) -> 0 | P26: =IFERROR(O26/12,"") -> 0
B27: Mantenimiento general extra | C27: =IFERROR('4a. Factibilidad'!C27,0) -> 0 | D27: =IFERROR('4a. Factibilidad'!D27,0) -> 0 | E27: =IFERROR('4a. Factibilidad'!E27,0) -> 0 | F27: =IFERROR('4a. Factibilidad'!F27,0) -> 0 | G27: =IFERROR('4a. Factibilidad'!G27,0) -> 0 | H27: =IFERROR('4a. Factibilidad'!H27,0) -> 0 | I27: =IFERROR('4a. Factibilidad'!I27,0) -> 0 | J27: =IFERROR('4a. Factibilidad'!J27,0) -> 0 | ... N27: =IFERROR('4a. Factibilidad'!N27,0) -> 0 | O27: =SUM(C27:N27) -> 0 | P27: =IFERROR(O27/12,"") -> 0 | Q27: Reparaciones menores imprevistas
B28: ='4a. Factibilidad'!B28 -> (agregar concepto) | C28: =IFERROR('4a. Factibilidad'!C28,0) -> 0 | D28: =IFERROR('4a. Factibilidad'!D28,0) -> 0 | E28: =IFERROR('4a. Factibilidad'!E28,0) -> 0 | F28: =IFERROR('4a. Factibilidad'!F28,0) -> 0 | G28: =IFERROR('4a. Factibilidad'!G28,0) -> 0 | H28: =IFERROR('4a. Factibilidad'!H28,0) -> 0 | I28: =IFERROR('4a. Factibilidad'!I28,0) -> 0 | J28: =IFERROR('4a. Factibilidad'!J28,0) -> 0 | ... N28: =IFERROR('4a. Factibilidad'!N28,0) -> 0 | O28: =SUM(C28:N28) -> 0 | P28: =IFERROR(O28/12,"") -> 0
B29: ='4a. Factibilidad'!B29 -> (agregar concepto) | C29: =IFERROR('4a. Factibilidad'!C29,0) -> 0 | D29: =IFERROR('4a. Factibilidad'!D29,0) -> 0 | E29: =IFERROR('4a. Factibilidad'!E29,0) -> 0 | F29: =IFERROR('4a. Factibilidad'!F29,0) -> 0 | G29: =IFERROR('4a. Factibilidad'!G29,0) -> 0 | H29: =IFERROR('4a. Factibilidad'!H29,0) -> 0 | I29: =IFERROR('4a. Factibilidad'!I29,0) -> 0 | J29: =IFERROR('4a. Factibilidad'!J29,0) -> 0 | ... N29: =IFERROR('4a. Factibilidad'!N29,0) -> 0 | O29: =SUM(C29:N29) -> 0 | P29: =IFERROR(O29/12,"") -> 0
B30: ='4a. Factibilidad'!B30 -> (agregar concepto) | C30: =IFERROR('4a. Factibilidad'!C30,0) -> 0 | D30: =IFERROR('4a. Factibilidad'!D30,0) -> 0 | E30: =IFERROR('4a. Factibilidad'!E30,0) -> 0 | F30: =IFERROR('4a. Factibilidad'!F30,0) -> 0 | G30: =IFERROR('4a. Factibilidad'!G30,0) -> 0 | H30: =IFERROR('4a. Factibilidad'!H30,0) -> 0 | I30: =IFERROR('4a. Factibilidad'!I30,0) -> 0 | J30: =IFERROR('4a. Factibilidad'!J30,0) -> 0 | ... N30: =IFERROR('4a. Factibilidad'!N30,0) -> 0 | O30: =SUM(C30:N30) -> 0 | P30: =IFERROR(O30/12,"") -> 0
B31: COSTOS FIJOS — escribe solo en Enero · los demás meses se repiten solos
B32: Hipoteca o renta del inmueble | C32: =IFERROR('4a. Factibilidad'!C32,0) -> 0 | D32: =$C$32 -> 0 | E32: =$C$32 -> 0 | F32: =$C$32 -> 0 | G32: =$C$32 -> 0 | H32: =$C$32 -> 0 | I32: =$C$32 -> 0 | J32: =$C$32 -> 0 | K32: =$C$32 -> 0 | ... N32: =$C$32 -> 0 | O32: =SUM(C32:N32) -> 0 | P32: =IFERROR(O32/12,"") -> 0 | Q32: ← Tab 1 · Perfil | más importante — fondo amarillo
B33: Seguro de propiedad | C33: =IFERROR('4a. Factibilidad'!C33,0) -> 0 | D33: =IFERROR('4a. Factibilidad'!D33,0) -> 0 | E33: =IFERROR('4a. Factibilidad'!E33,0) -> 0 | F33: =IFERROR('4a. Factibilidad'!F33,0) -> 0 | G33: =IFERROR('4a. Factibilidad'!G33,0) -> 0 | H33: =IFERROR('4a. Factibilidad'!H33,0) -> 0 | I33: =IFERROR('4a. Factibilidad'!I33,0) -> 0 | J33: =IFERROR('4a. Factibilidad'!J33,0) -> 0 | ... N33: =IFERROR('4a. Factibilidad'!N33,0) -> 0 | O33: =SUM(C33:N33) -> 0 | P33: =IFERROR(O33/12,"") -> 0 | Q33: Prorateado mensual
B34: Impuesto de la propiedad (prorateado mensual) | C34: =IFERROR('4a. Factibilidad'!C34,0) -> 0 | D34: =IFERROR('4a. Factibilidad'!D34,0) -> 0 | E34: =IFERROR('4a. Factibilidad'!E34,0) -> 0 | F34: =IFERROR('4a. Factibilidad'!F34,0) -> 0 | G34: =IFERROR('4a. Factibilidad'!G34,0) -> 0 | H34: =IFERROR('4a. Factibilidad'!H34,0) -> 0 | I34: =IFERROR('4a. Factibilidad'!I34,0) -> 0 | J34: =IFERROR('4a. Factibilidad'!J34,0) -> 0 | ... N34: =IFERROR('4a. Factibilidad'!N34,0) -> 0 | O34: =SUM(C34:N34) -> 0 | P34: =IFERROR(O34/12,"") -> 0
B35: Internet de alta velocidad | C35: 0 | D35: =$C$35 -> 0 | E35: =$C$35 -> 0 | F35: =$C$35 -> 0 | G35: =$C$35 -> 0 | H35: =$C$35 -> 0 | I35: =$C$35 -> 0 | J35: =$C$35 -> 0 | K35: =$C$35 -> 0 | ... N35: =$C$35 -> 0 | O35: =SUM(C35:N35) -> 0 | P35: =IFERROR(O35/12,"") -> 0
B36: ='4a. Factibilidad'!B36 -> (agregar concepto) | C36: =IFERROR('4a. Factibilidad'!C36,0) -> 0 | D36: =IFERROR('4a. Factibilidad'!D36,0) -> 0 | E36: =IFERROR('4a. Factibilidad'!E36,0) -> 0 | F36: =IFERROR('4a. Factibilidad'!F36,0) -> 0 | G36: =IFERROR('4a. Factibilidad'!G36,0) -> 0 | H36: =IFERROR('4a. Factibilidad'!H36,0) -> 0 | I36: =IFERROR('4a. Factibilidad'!I36,0) -> 0 | J36: =IFERROR('4a. Factibilidad'!J36,0) -> 0 | ... N36: =IFERROR('4a. Factibilidad'!N36,0) -> 0 | O36: =SUM(C36:N36) -> 0 | P36: =IFERROR(O36/12,"") -> 0
B37: ='4a. Factibilidad'!B37 -> (agregar concepto) | C37: =IFERROR('4a. Factibilidad'!C37,0) -> 0 | D37: =IFERROR('4a. Factibilidad'!D37,0) -> 0 | E37: =IFERROR('4a. Factibilidad'!E37,0) -> 0 | F37: =IFERROR('4a. Factibilidad'!F37,0) -> 0 | G37: =IFERROR('4a. Factibilidad'!G37,0) -> 0 | H37: =IFERROR('4a. Factibilidad'!H37,0) -> 0 | I37: =IFERROR('4a. Factibilidad'!I37,0) -> 0 | J37: =IFERROR('4a. Factibilidad'!J37,0) -> 0 | ... N37: =IFERROR('4a. Factibilidad'!N37,0) -> 0 | O37: =SUM(C37:N37) -> 0 | P37: =IFERROR(O37/12,"") -> 0
B38: ='4a. Factibilidad'!B38 -> (agregar concepto) | C38: =IFERROR('4a. Factibilidad'!C38,0) -> 0 | D38: =IFERROR('4a. Factibilidad'!D38,0) -> 0 | E38: =IFERROR('4a. Factibilidad'!E38,0) -> 0 | F38: =IFERROR('4a. Factibilidad'!F38,0) -> 0 | G38: =IFERROR('4a. Factibilidad'!G38,0) -> 0 | H38: =IFERROR('4a. Factibilidad'!H38,0) -> 0 | I38: =IFERROR('4a. Factibilidad'!I38,0) -> 0 | J38: =IFERROR('4a. Factibilidad'!J38,0) -> 0 | ... N38: =IFERROR('4a. Factibilidad'!N38,0) -> 0 | O38: =SUM(C38:N38) -> 0 | P38: =IFERROR(O38/12,"") -> 0
B39: ='4a. Factibilidad'!B39 -> Comisión plataforma (Airbnb) | C39: =IFERROR('4a. Factibilidad'!C39,0) -> 0 | D39: =IFERROR('4a. Factibilidad'!D39,0) -> 0 | E39: =IFERROR('4a. Factibilidad'!E39,0) -> 0 | F39: =IFERROR('4a. Factibilidad'!F39,0) -> 0 | G39: =IFERROR('4a. Factibilidad'!G39,0) -> 0 | H39: =IFERROR('4a. Factibilidad'!H39,0) -> 0 | I39: =IFERROR('4a. Factibilidad'!I39,0) -> 0 | J39: =IFERROR('4a. Factibilidad'!J39,0) -> 0 | ... N39: =IFERROR('4a. Factibilidad'!N39,0) -> 0 | O39: =SUM(C39:N39) -> 0 | P39: =IFERROR(O39/12,"") -> 0
B40: COSTOS VARIABLES — varían cada mes · ingresa el importe real
...

Sheet 5. Resumen
B2: RESUMEN EJECUTIVO — Estudio de Factibilidad Vacacional
B3: Todo se actualiza automáticamente desde las otras pestañas. Este es el documento que se presenta y entrega al cliente.
B5: 1. PROPIEDAD
B6: Cliente / Anfitrión | C6: ='1. Perfil'!C8 -> Ej. Nombre del anfitrión o empresa
B7: Propiedad | C7: ='1. Perfil'!C4 -> Ej. Estudio Long Island
B8: Tipo de alojamiento | C8: ='1. Perfil'!C5 -> Ej. Departamento completo
B9: Ciudad / Zona | C9: ='1. Perfil'!C6 -> Ej. Elmont, NY
B10: Moneda del estudio | C10: ='1. Perfil'!C2 -> USD - Dólar EE.UU.
B11: Capacidad (huéspedes) | C11: ='1. Perfil'!C13 -> 0
B13: 2. RESULTADOS DEL ESTUDIO DE MERCADO
B14: Promedios de 10 propiedades comparables analizadas en "2. Mercado"
B15: Métrica | C15: Mi propiedad | D15: Promedio mercado | E15: Mi posición
B16: Tarifa promedio por noche | C16: =IFERROR('2. Mercado'!Y14,"") | D16: =IFERROR('2. Mercado'!Y15,"") | E16: =IFERROR(IF(D16=0,"",IF(C16>=D16,"↑ "&TEXT((C16-D16)/D16,"0.0%")&" arriba","↓ "&TEXT((D16-C16)/D16,"0.0%")&" abajo")),"")
B17: Ocupación estimada | C17: =IFERROR('2. Mercado'!Z14,"") -> 0 | D17: =IFERROR('2. Mercado'!Z15,"") | E17: =IFERROR(IF(D17=0,"",IF(C17>=D17,"↑ "&TEXT(C17-D17,"0.0%")&" arriba","↓ "&TEXT(D17-C17,"0.0%")&" abajo")),"")
B18: Ingreso mensual estimado (bruto) | C18: =IFERROR('2. Mercado'!AA14,"") | D18: =IFERROR('2. Mercado'!AA15,"") | E18: =IFERROR(IF(D18=0,"",IF(C18>=D18,"↑ "&TEXT((C18-D18)/D18,"0.0%"),"↓ "&TEXT((D18-C18)/D18,"0.0%"))),"")
B19: Reviews promedio (total) | C19: =IFERROR('2. Mercado'!H14,"") -> 0 | D19: =IFERROR('2. Mercado'!H15,"")
B20: Rating promedio | C20: =IFERROR('2. Mercado'!I14,"") -> 0 | D20: =IFERROR('2. Mercado'!I15,"")
B21: Reviews / año (velocidad) | C21: =IFERROR('2. Mercado'!L14,"") | D21: =IFERROR('2. Mercado'!L15,"")
B23: 3. TECHO DE MERCADO — TOP 5 PROPIEDADES
B24: El potencial máximo de tu zona, basado en las 5 propiedades de mayor revenue (ver "3. Top Propiedades")
B25: Revenue máximo (top 1) | C25: =IFERROR('3. Top Propiedades'!C12,"") -> 0
B26: Revenue promedio top 5 | C26: =IFERROR('3. Top Propiedades'!C13,"") -> 0
B27: Tarifa promedio noche top 5 | C27: =IFERROR('3. Top Propiedades'!C14,"")
B28: Brecha vs mercado base | C28: =IFERROR('3. Top Propiedades'!C15,"")
B30: 4. FACTIBILIDAD — COMPARATIVO DE 3 ESCENARIOS
B31: Resultados anuales y mensuales de los 3 escenarios. Todos descuentan comisión Airbnb, gastos operativos y reserva.
B32: Métrica | C32: Factibilidad (4a) | D32: Aspiracional (4b) | E32: Techo de Mercado (4c)
B33: INGRESO ANUAL (bruto) | C33: =IFERROR('4a. Factibilidad'!O12,"") -> 0 | D33: =IFERROR('4b. Aspiracional'!O12,"") -> 0 | E33: =IFERROR('4c. Techo de Mercado'!O12,"") -> 0
B34: Ingreso mensual promedio | C34: =IFERROR('4a. Factibilidad'!P12,"") -> 0 | D34: =IFERROR('4b. Aspiracional'!P12,"") -> 0 | E34: =IFERROR('4c. Techo de Mercado'!P12,"") -> 0
